<mujoco model="eco65_with_2f85_and_d435i">
  <compiler angle="radian" meshdir="." autolimits="true" balanceinertia="true"/>
  <option integrator="implicitfast"/>

  <default>
    <default class="eco65">
      <material specular="0.5" shininess="0.25"/>
      <joint axis="0 0 1" range="-6.28319 6.28319" armature="0.1"/>
      <general biastype="affine" ctrlrange="-6.2831 6.2831" gainprm="5000" biasprm="0 -5000 -500"/>
      <default class="joint_big">
        <joint damping="10"/>
        <general forcerange="-330 330"/>
      </default>
      <default class="joint_medium">
        <joint damping="5"/>
        <general forcerange="-150 150"/>
      </default>
      <default class="joint_small">
        <joint damping="2"/>
        <general forcerange="-56 56"/>
      </default>
      <default class="visual_eco65">
        <geom type="mesh" contype="0" conaffinity="0" group="2"/>
      </default>
      <default class="collision_eco65">
        <geom type="capsule" group="3"/>
      </default>
    </default>

    <default class="2f85">
      <mesh scale="0.001 0.001 0.001"/>
      <general biastype="affine"/>
      <joint axis="1 0 0"/>
      <default class="driver">
        <joint range="0 0.8" armature="0.005" damping="0.1"
               solimplimit="0.95 0.99 0.001" solreflimit="0.005 1"/>
      </default>
      <default class="follower">
        <joint range="-0.872664 0.872664" armature="0.001" pos="0 -0.018 0.0065"
               solimplimit="0.95 0.99 0.001" solreflimit="0.005 1"/>
      </default>
      <default class="spring_link">
        <joint range="-0.29670597283 0.8" armature="0.001" stiffness="0.05"
               springref="2.62" damping="0.00125"/>
      </default>
      <default class="coupler">
        <joint range="-1.57 0" armature="0.001"
               solimplimit="0.95 0.99 0.001" solreflimit="0.005 1"/>
      </default>
      <default class="visual_2f85">
        <geom type="mesh" contype="0" conaffinity="0" group="2"/>
      </default>
      <default class="collision_2f85">
        <geom type="mesh" group="3"/>
        <default class="pad_box1">
          <geom mass="0" type="box" pos="0 -0.0026 0.028125" size="0.011 0.004 0.009375"
                friction="0.7" solimp="0.95 0.99 0.001" solref="0.004 1"
                priority="1" rgba="0.55 0.55 0.55 1"/>
        </default>
        <default class="pad_box2">
          <geom mass="0" type="box" pos="0 -0.0026 0.009375" size="0.011 0.004 0.009375"
                friction="0.6" solimp="0.95 0.99 0.001" solref="0.004 1"
                priority="1" rgba="0.45 0.45 0.45 1"/>
        </default>
      </default>
    </default>

    <default class="d435i">
      <material specular="0" shininess="0.25"/>
      <default class="d435i_visual">
        <geom group="2" type="mesh" contype="0" conaffinity="0" mass="0"/>
      </default>
      <default class="d435i_collision">
        <geom group="3" type="mesh" mass="0"/>
      </default>
    </default>
  </default>

  <asset>
    <!-- ECO65 materials and meshes -->
    <material class="eco65" name="eco65_body" rgba="0.9 0.9 0.9 1"/>
    <material class="eco65" name="eco65_joint" rgba="0.3 0.3 0.3 1"/>
    <material class="eco65" name="eco65_base" rgba="0.15 0.15 0.15 1"/>
    <mesh class="eco65" name="eco65_base_link" file="eco65_meshes/base_link.STL"/>
    <mesh class="eco65" name="eco65_link_1" file="eco65_meshes/link_1.STL"/>
    <mesh class="eco65" name="eco65_link_2" file="eco65_meshes/link_2.STL"/>
    <mesh class="eco65" name="eco65_link_3" file="eco65_meshes/link_3.STL"/>
    <mesh class="eco65" name="eco65_link_4" file="eco65_meshes/link_4.STL"/>
    <mesh class="eco65" name="eco65_link_5" file="eco65_meshes/link_5.STL"/>
    <mesh class="eco65" name="eco65_link_6" file="eco65_meshes/link_6.STL"/>

    <!-- Robotiq 2F-85 materials and meshes -->
    <material name="metal" rgba="0.58 0.58 0.58 1"/>
    <material name="silicone" rgba="0.1882 0.1882 0.1882 1"/>
    <material name="gripper_gray" rgba="0.4627 0.4627 0.4627 1"/>
    <material name="gripper_black" rgba="0.149 0.149 0.149 1"/>
    <mesh class="2f85" file="robotiq_2f85/assets/base_mount.stl"/>
    <mesh class="2f85" file="robotiq_2f85/assets/base.stl"/>
    <mesh class="2f85" file="robotiq_2f85/assets/driver.stl"/>
    <mesh class="2f85" file="robotiq_2f85/assets/coupler.stl"/>
    <mesh class="2f85" file="robotiq_2f85/assets/follower.stl"/>
    <mesh class="2f85" file="robotiq_2f85/assets/pad.stl"/>
    <mesh class="2f85" file="robotiq_2f85/assets/silicone_pad.stl"/>
    <mesh class="2f85" file="robotiq_2f85/assets/spring_link.stl"/>

    <!-- D435i materials and meshes -->
    <material class="d435i" name="Black_Acrylic" rgba="0.070360 0.070360 0.070360 1"/>
    <material class="d435i" name="Cameras_Gray" rgba="0.296138 0.296138 0.296138 1"/>
    <material class="d435i" name="IR_Emitter_Lens" rgba="0.287440 0.665387 0.327778 1"/>
    <material class="d435i" name="IR_Lens" rgba="0.035601 0.035601 0.035601 1"/>
    <material class="d435i" name="IR_Rim" rgba="0.799102 0.806952 0.799103 1"/>
    <material class="d435i" name="Metal_Casing" rgba="1 1 1 1"/>
    <material class="d435i" name="RGB_Pupil" rgba="0.087140 0.002866 0.009346 1"/>
    <mesh file="realsense_d435i/assets/d435i_0.obj"/>
    <mesh file="realsense_d435i/assets/d435i_1.obj"/>
    <mesh file="realsense_d435i/assets/d435i_2.obj"/>
    <mesh file="realsense_d435i/assets/d435i_3.obj"/>
    <mesh file="realsense_d435i/assets/d435i_4.obj"/>
    <mesh file="realsense_d435i/assets/d435i_5.obj"/>
    <mesh file="realsense_d435i/assets/d435i_6.obj"/>
    <mesh file="realsense_d435i/assets/d435i_7.obj"/>
    <mesh file="realsense_d435i/assets/d435i_8.obj"/>
  </asset>

  <worldbody>
    <light name="spotlight" mode="targetbodycom" target="link_5" pos="0 -1 2"/>

    <!-- ==================== ECO65-6FB Robot Arm ==================== -->
    <body name="base" pos="0.6 0 0.8" quat="0 0 0 -1" childclass="eco65">
      <inertial mass="2.0" pos="0.0004101 -8.4575e-05 0.050471"
                diaginertia="0.0011075 0.001109 0.00075402"/>
      <geom mesh="eco65_base_link" material="eco65_base" class="visual_eco65"/>
      <geom class="collision_eco65" type="capsule" size="0.06 0.08" pos="0 0 0.05"/>

      <body name="joint_1_origin" pos="0 0 0.1625">
        <body name="link_1">
          <inertial mass="1.507" pos="-0.01105 2.736e-05 -0.03347"
                    diaginertia="0.001958 0.003101 0.002427"/>
          <joint name="joint_1" class="joint_big" range="-3.106 3.106"/>
          <geom mesh="eco65_link_1" material="eco65_body" class="visual_eco65"/>
          <geom class="collision_eco65" size="0.06 0.05" pos="0 0 -0.03"/>

          <body name="joint_2_origin" pos="-0.086 0 0" quat="-0.49999816 0.50000184 0.5 0.5">
            <body name="link_2">
              <inertial mass="2.0227" pos="0.05818 -1.163e-05 -0.05236"
                        diaginertia="0.002274 0.017311 0.017226"/>
              <joint name="joint_2" class="joint_big" range="-3.106 2.356"/>
              <geom mesh="eco65_link_2" material="eco65_body" class="visual_eco65"/>
              <geom class="collision_eco65" size="0.06 0.13" pos="0.13 0 0"/>

              <body name="joint_3_origin" pos="0.26 0 0">
                <body name="link_3">
                  <inertial mass="1.8858" pos="0.092768 -9.3866e-05 0.00181"
                            diaginertia="0.001916 0.022483 0.021893"/>
                  <joint name="joint_3" class="joint_medium" range="-2.792 2.53"/>
                  <geom mesh="eco65_link_3" material="eco65_body" class="visual_eco65"/>
                  <geom class="collision_eco65" size="0.05 0.12" pos="0.12 0 0"/>

                  <body name="joint_4_origin" pos="0.24 0 -0.05888" quat="0.70710548 0 0 0.70710808">
                    <body name="link_4">
                      <inertial mass="0.57" pos="-4.028e-05 -0.03496 0.0038015"
                                diaginertia="0.000498 0.000325 0.001163"/>
                      <joint name="joint_4" class="joint_small" range="-3.106 3.106"/>
                      <geom mesh="eco65_link_4" material="eco65_body" class="visual_eco65"/>
                      <geom class="collision_eco65" size="0.04 0.055" pos="0 0 0"/>

                      <body name="joint_5_origin" pos="0 -0.11 0" quat="0.70710548 0.70710808 0 0">
                        <body name="link_5">
                          <inertial mass="0.641" pos="-3.97e-05 0.022647 -0.007365"
                                    diaginertia="0.000623 0.000393 0.000557"/>
                          <joint name="joint_5" class="joint_small" range="-3.106 3.106"/>
                          <geom mesh="eco65_link_5" material="eco65_body" class="visual_eco65"/>
                          <geom class="collision_eco65" size="0.04 0.05" pos="0 0.025 0"/>

                          <body name="joint_6_origin" pos="0 0.0967 0" quat="0.70710548 -0.70710808 0 0">
                            <body name="link_6">
                              <inertial mass="0.0857" pos="0.0004478 -0.0002134 -0.01033579"
                                        diaginertia="3.302707e-05 3.0206675e-05 5.1459675e-05"/>
                              <joint name="joint_6" class="joint_small" range="-6.28 6.28"/>
                              <geom mesh="eco65_link_6" material="eco65_body" class="visual_eco65"/>
                              <geom class="collision_eco65" type="cylinder" size="0.04 0.015" pos="0 0 -0.005"/>

                              <site name="attachment_site" pos="0 0 0" quat="-1 1 0 0"/>

                              <!-- ==================== D435i Camera ==================== -->
                              <body name="d435i_camera" pos="-0.05 0.00 -0.03" quat="0.707107 0 0 0.707107" childclass="d435i">
                                <geom mesh="d435i_0" material="IR_Lens" class="d435i_visual"/>
                                <geom mesh="d435i_1" material="IR_Emitter_Lens" class="d435i_visual"/>
                                <geom mesh="d435i_2" material="IR_Rim" class="d435i_visual"/>
                                <geom mesh="d435i_3" material="IR_Lens" class="d435i_visual"/>
                                <geom mesh="d435i_4" material="Cameras_Gray" class="d435i_visual"/>
                                <geom mesh="d435i_5" material="Black_Acrylic" class="d435i_visual"/>
                                <geom mesh="d435i_6" material="Black_Acrylic" class="d435i_visual"/>
                                <geom mesh="d435i_7" material="RGB_Pupil" class="d435i_visual"/>
                                <geom mesh="d435i_8" mass="0.072" material="Metal_Casing" class="d435i_visual"/>
                                <geom class="d435i_collision" type="capsule" mesh="d435i_8"/>
                                <camera name="d435i_rgb" mode="fixed" pos="0 0 0" fovy="42.5" euler="0 3.14159 0"/>
                              </body>

                              <!-- ==================== Robotiq 2F-85 Gripper ==================== -->
                              <body name="gripper_mount_point" pos="0 0 0" quat="1 0 0 0">
                                <body name="base_mount" pos="0 0 0.007" childclass="2f85">
                                  <geom class="visual_2f85" mesh="base_mount" material="gripper_black"/>
                                  <geom class="collision_2f85" mesh="base_mount"/>
                                  <body name="gripper_base" pos="0 0 0.0038" quat="1 0 0 -1">
                                    <inertial mass="0.777441" pos="0 -2.70394e-05 0.0354675"
                                              quat="1 -0.00152849 0 0"
                                              diaginertia="0.000260285 0.000225381 0.000152708"/>
                                    <geom class="visual_2f85" mesh="base" material="gripper_black"/>
                                    <geom class="collision_2f85" mesh="base"/>
                                    <site name="pinch" pos="0 0 0.145" type="sphere" group="5"
                                          rgba="0.9 0.9 0.9 1" size="0.005"/>
                                    <body name="right_driver" pos="0 0.0306011 0.054904">
                                      <inertial mass="0.00899563" pos="2.96931e-12 0.0177547 0.00107314"
                                                quat="0.681301 0.732003 0 0"
                                                diaginertia="1.72352e-06 1.60906e-06 3.22006e-07"/>
                                      <joint name="right_driver_joint" class="driver"/>
                                      <geom class="visual_2f85" mesh="driver" material="gripper_gray"/>
                                      <geom class="collision_2f85" mesh="driver"/>
                                      <body name="right_coupler" pos="0 0.0315 -0.0041">
                                        <inertial mass="0.0140974" pos="0 0.00301209 0.0232175"
                                                  quat="0.705636 -0.0455904 0.0455904 0.705636"
                                                  diaginertia="4.16206e-06 3.52216e-06 8.88131e-07"/>
                                        <joint name="right_coupler_joint" class="coupler"/>
                                        <geom class="visual_2f85" mesh="coupler" material="gripper_black"/>
                                        <geom class="collision_2f85" mesh="coupler"/>
                                      </body>
                                    </body>
                                    <body name="right_spring_link" pos="0 0.0132 0.0609">
                                      <inertial mass="0.0221642" pos="-8.65005e-09 0.0181624 0.0212658"
                                                quat="0.663403 -0.244737 0.244737 0.663403"
                                                diaginertia="8.96853e-06 6.71733e-06 2.63931e-06"/>
                                      <joint name="right_spring_link_joint" class="spring_link"/>
                                      <geom class="visual_2f85" mesh="spring_link" material="gripper_black"/>
                                      <geom class="collision_2f85" mesh="spring_link"/>
                                      <body name="right_follower" pos="0 0.055 0.0375">
                                        <inertial mass="0.0125222" pos="0 -0.011046 0.0124786"
                                                  quat="1 0.1664 0 0"
                                                  diaginertia="2.67415e-06 2.4559e-06 6.02031e-07"/>
                                        <joint name="right_follower_joint" class="follower"/>
                                        <geom class="visual_2f85" mesh="follower" material="gripper_black"/>
                                        <geom class="collision_2f85" mesh="follower"/>
                                        <body name="right_pad" pos="0 -0.0189 0.01352">
                                          <geom class="pad_box1" name="right_pad1"/>
                                          <geom class="pad_box2" name="right_pad2"/>
                                          <inertial mass="0.0035" pos="0 -0.0025 0.0185"
                                                    quat="0.707107 0 0 0.707107"
                                                    diaginertia="4.73958e-07 3.64583e-07 1.23958e-07"/>
                                          <geom class="visual_2f85" mesh="pad"/>
                                          <body name="right_silicone_pad">
                                            <geom class="visual_2f85" mesh="silicone_pad" material="gripper_black"/>
                                          </body>
                                        </body>
                                      </body>
                                    </body>
                                    <body name="left_driver" pos="0 -0.0306011 0.054904" quat="0 0 0 1">
                                      <inertial mass="0.00899563" pos="0 0.0177547 0.00107314"
                                                quat="0.681301 0.732003 0 0"
                                                diaginertia="1.72352e-06 1.60906e-06 3.22006e-07"/>
                                      <joint name="left_driver_joint" class="driver"/>
                                      <geom class="visual_2f85" mesh="driver" material="gripper_gray"/>
                                      <geom class="collision_2f85" mesh="driver"/>
                                      <body name="left_coupler" pos="0 0.0315 -0.0041">
                                        <inertial mass="0.0140974" pos="0 0.00301209 0.0232175"
                                                  quat="0.705636 -0.0455904 0.0455904 0.705636"
                                                  diaginertia="4.16206e-06 3.52216e-06 8.88131e-07"/>
                                        <joint name="left_coupler_joint" class="coupler"/>
                                        <geom class="visual_2f85" mesh="coupler" material="gripper_black"/>
                                        <geom class="collision_2f85" mesh="coupler"/>
                                      </body>
                                    </body>
                                    <body name="left_spring_link" pos="0 -0.0132 0.0609" quat="0 0 0 1">
                                      <inertial mass="0.0221642" pos="-8.65005e-09 0.0181624 0.0212658"
                                                quat="0.663403 -0.244737 0.244737 0.663403"
                                                diaginertia="8.96853e-06 6.71733e-06 2.63931e-06"/>
                                      <joint name="left_spring_link_joint" class="spring_link"/>
                                      <geom class="visual_2f85" mesh="spring_link" material="gripper_black"/>
                                      <geom class="collision_2f85" mesh="spring_link"/>
                                      <body name="left_follower" pos="0 0.055 0.0375">
                                        <inertial mass="0.0125222" pos="0 -0.011046 0.0124786"
                                                  quat="1 0.1664 0 0"
                                                  diaginertia="2.67415e-06 2.4559e-06 6.02031e-07"/>
                                        <joint name="left_follower_joint" class="follower"/>
                                        <geom class="visual_2f85" mesh="follower" material="gripper_black"/>
                                        <geom class="collision_2f85" mesh="follower"/>
                                        <body name="left_pad" pos="0 -0.0189 0.01352">
                                          <geom class="pad_box1" name="left_pad1"/>
                                          <geom class="pad_box2" name="left_pad2"/>
                                          <inertial mass="0.0035" pos="0 -0.0025 0.0185"
                                                    quat="1 0 0 1"
                                                    diaginertia="4.73958e-07 3.64583e-07 1.23958e-07"/>
                                          <geom class="visual_2f85" mesh="pad"/>
                                          <body name="left_silicone_pad">
                                            <geom class="visual_2f85" mesh="silicone_pad" material="gripper_black"/>
                                            <geom class="visual_2f85" mesh="silicone_pad" material="gripper_black"/>
                                          </body>
                                        </body>
                                      </body>
                                    </body>
                                  </body>
                                </body>
                              </body>
                            </body>
                          </body>
                        </body>
                      </body>
                    </body>
                  </body>
                </body>
              </body>
            </body>
          </body>
        </body>
      </body>
    </body>
  </worldbody>

  <contact>
    <exclude body1="gripper_base" body2="left_driver"/>
    <exclude body1="gripper_base" body2="right_driver"/>
    <exclude body1="gripper_base" body2="left_spring_link"/>
    <exclude body1="gripper_base" body2="right_spring_link"/>
    <exclude body1="right_coupler" body2="right_follower"/>
    <exclude body1="left_coupler" body2="left_follower"/>
  </contact>

  <tendon>
    <fixed name="split">
      <joint joint="right_driver_joint" coef="0.5"/>
      <joint joint="left_driver_joint" coef="0.5"/>
    </fixed>
  </tendon>

  <equality>
    <connect anchor="0 0 0" body1="right_follower" body2="right_coupler"
             solimp="0.95 0.99 0.001" solref="0.005 1"/>
    <connect anchor="0 0 0" body1="left_follower" body2="left_coupler"
             solimp="0.95 0.99 0.001" solref="0.005 1"/>
    <joint joint1="right_driver_joint" joint2="left_driver_joint" polycoef="0 1 0 0 0"
           solimp="0.95 0.99 0.001" solref="0.005 1"/>
  </equality>

  <actuator>
    <general class="joint_big" name="joint1" joint="joint_1"/>
    <general class="joint_big" name="joint2" joint="joint_2"/>
    <general class="joint_medium" name="joint3" joint="joint_3"/>
    <general class="joint_small" name="joint4" joint="joint_4"/>
    <general class="joint_small" name="joint5" joint="joint_5"/>
    <general class="joint_small" name="joint6" joint="joint_6"/>
    <general class="2f85" name="fingers_actuator" tendon="split"
             forcerange="-5 5" ctrlrange="0 255"
             gainprm="0.3137255 0 0" biasprm="0 -100 -10"/>
  </actuator>

</mujoco>
